Workbook

Sheet Detalle
A1: usuario_id | B1: timestamp | C1: letra (predicha) | D1: confianza | E1: modelo | F1: latencia_ms | G1: letra_ejecutada | H1: correcto | I1: evaluada_por_oyente (1=sí) | J1: letra_entendida_oyente | K1: comprendido
A2: 1 | B2: 46258.375 | C2: Ñ | D2: 0.879 | E2: DIN | F2: 123.802 | G2: Ñ | H2: =IF(C2=G2,1,0) -> 1 | I2: 1 | J2: Ñ | K2: =IF(J2="","",IF(J2=G2,1,0)) -> 1
A3: 1 | B3: 46258.375 | C3: V | D3: 0.886 | E3: EST | F3: 100.536 | G3: V | H3: =IF(C3=G3,1,0) -> 1 | I3: 1 | J3: V | K3: =IF(J3="","",IF(J3=G3,1,0)) -> 1
A4: 1 | B4: 46258.375 | C4: P | D4: 0.934 | E4: EST | F4: 98.796 | G4: P | H4: =IF(C4=G4,1,0) -> 1 | K4: =IF(J4="","",IF(J4=G4,1,0))
A5: 1 | B5: 46258.375 | C5: U | D5: 0.883 | E5: EST | F5: 116.096 | G5: U | H5: =IF(C5=G5,1,0) -> 1 | I5: 1 | J5: U | K5: =IF(J5="","",IF(J5=G5,1,0)) -> 1
A6: 1 | B6: 46258.376 | C6: S | D6: 0.871 | E6: EST | F6: 116.129 | G6: S | H6: =IF(C6=G6,1,0) -> 1 | I6: 1 | J6: S | K6: =IF(J6="","",IF(J6=G6,1,0)) -> 1
A7: 1 | B7: 46258.376 | C7: Q | D7: 0.781 | E7: EST | F7: 86.223 | G7: Q | H7: =IF(C7=G7,1,0) -> 1 | K7: =IF(J7="","",IF(J7=G7,1,0))
A8: 1 | B8: 46258.376 | C8: N | D8: 0.924 | E8: EST | F8: 103.976 | G8: N | H8: =IF(C8=G8,1,0) -> 1 | I8: 1 | J8: N | K8: =IF(J8="","",IF(J8=G8,1,0)) -> 1
A9: 1 | B9: 46258.376 | C9: Z | D9: 0.775 | E9: DIN | F9: 151.932 | G9: Z | H9: =IF(C9=G9,1,0) -> 1 | K9: =IF(J9="","",IF(J9=G9,1,0))
A10: 1 | B10: 46258.376 | C10: Y | D10: 0.858 | E10: EST | F10: 124.917 | G10: Y | H10: =IF(C10=G10,1,0) -> 1 | K10: =IF(J10="","",IF(J10=G10,1,0))
A11: 1 | B11: 46258.376 | C11: F | D11: 0.697 | E11: EST | F11: 138.804 | G11: B | H11: =IF(C11=G11,1,0) -> 0 | I11: 1 | J11: F | K11: =IF(J11="","",IF(J11=G11,1,0)) -> 0
A12: 1 | B12: 46258.376 | C12: L | D12: 0.83 | E12: EST | F12: 134.017 | G12: L | H12: =IF(C12=G12,1,0) -> 1 | K12: =IF(J12="","",IF(J12=G12,1,0))
A13: 1 | B13: 46258.377 | C13: C | D13: 0.868 | E13: EST | F13: 118.138 | G13: C | H13: =IF(C13=G13,1,0) -> 1 | I13: 1 | J13: C | K13: =IF(J13="","",IF(J13=G13,1,0)) -> 1
A14: 1 | B14: 46258.377 | C14: G | D14: 0.886 | E14: EST | F14: 119.482 | G14: G | H14: =IF(C14=G14,1,0) -> 1 | K14: =IF(J14="","",IF(J14=G14,1,0))
A15: 1 | B15: 46258.377 | C15: J | D15: 0.858 | E15: DIN | F15: 127.228 | G15: J | H15: =IF(C15=G15,1,0) -> 1 | I15: 1 | J15: J | K15: =IF(J15="","",IF(J15=G15,1,0)) -> 1
A16: 1 | B16: 46258.377 | C16: B | D16: 0.745 | E16: EST | F16: 118.791 | G16: W | H16: =IF(C16=G16,1,0) -> 0 | I16: 1 | J16: B | K16: =IF(J16="","",IF(J16=G16,1,0)) -> 0
A17: 1 | B17: 46258.377 | C17: E | D17: 0.906 | E17: EST | F17: 120.56 | G17: E | H17: =IF(C17=G17,1,0) -> 1 | I17: 1 | J17: E | K17: =IF(J17="","",IF(J17=G17,1,0)) -> 1
A18: 1 | B18: 46258.378 | C18: I | D18: 0.875 | E18: EST | F18: 97.323 | G18: I | H18: =IF(C18=G18,1,0) -> 1 | K18: =IF(J18="","",IF(J18=G18,1,0))
A19: 1 | B19: 46258.378 | C19: D | D19: 0.931 | E19: EST | F19: 85 | G19: D | H19: =IF(C19=G19,1,0) -> 1 | K19: =IF(J19="","",IF(J19=G19,1,0))
A20: 1 | B20: 46258.378 | C20: K | D20: 0.908 | E20: EST | F20: 116.417 | G20: K | H20: =IF(C20=G20,1,0) -> 1 | K20: =IF(J20="","",IF(J20=G20,1,0))
A21: 1 | B21: 46258.378 | C21: H | D21: 0.859 | E21: EST | F21: 122.569 | G21: H | H21: =IF(C21=G21,1,0) -> 1 | K21: =IF(J21="","",IF(J21=G21,1,0))
A22: 1 | B22: 46258.378 | C22: T | D22: 0.853 | E22: EST | F22: 97.079 | G22: T | H22: =IF(C22=G22,1,0) -> 1 | K22: =IF(J22="","",IF(J22=G22,1,0))
A23: 1 | B23: 46258.378 | C23: R | D23: 0.891 | E23: EST | F23: 112.009 | G23: R | H23: =IF(C23=G23,1,0) -> 1 | K23: =IF(J23="","",IF(J23=G23,1,0))
A24: 1 | B24: 46258.378 | C24: O | D24: 0.922 | E24: EST | F24: 94.284 | G24: O | H24: =IF(C24=G24,1,0) -> 1 | K24: =IF(J24="","",IF(J24=G24,1,0))
A25: 1 | B25: 46258.379 | C25: X | D25: 0.862 | E25: EST | F25: 109.796 | G25: X | H25: =IF(C25=G25,1,0) -> 1 | K25: =IF(J25="","",IF(J25=G25,1,0))
A26: 1 | B26: 46258.379 | C26: Q | D26: 0.777 | E26: EST | F26: 102.442 | G26: Q | H26: =IF(C26=G26,1,0) -> 1 | K26: =IF(J26="","",IF(J26=G26,1,0))
A27: 1 | B27: 46258.379 | C27: J | D27: 0.766 | E27: DIN | F27: 132.694 | G27: I | H27: =IF(C27=G27,1,0) -> 0 | K27: =IF(J27="","",IF(J27=G27,1,0))
A28: 1 | B28: 46258.379 | C28: N | D28: 0.869 | E28: EST | F28: 85 | G28: N | H28: =IF(C28=G28,1,0) -> 1 | K28: =IF(J28="","",IF(J28=G28,1,0))
A29: 1 | B29: 46258.379 | C29: Q | D29: 0.954 | E29: EST | F29: 103.158 | G29: Q | H29: =IF(C29=G29,1,0) -> 1 | K29: =IF(J29="","",IF(J29=G29,1,0))
A30: 1 | B30: 46258.379 | C30: J | D30: 0.912 | E30: DIN | F30: 134.811 | G30: J | H30: =IF(C30=G30,1,0) -> 1 | K30: =IF(J30="","",IF(J30=G30,1,0))
A31: 1 | B31: 46258.379 | C31: U | D31: 0.842 | E31: EST | F31: 141.259 | G31: U | H31: =IF(C31=G31,1,0) -> 1 | I31: 1 | J31: U | K31: =IF(J31="","",IF(J31=G31,1,0)) -> 1
A32: 1 | B32: 46258.38 | C32: U | D32: 0.862 | E32: EST | F32: 102.839 | G32: U | H32: =IF(C32=G32,1,0) -> 1 | K32: =IF(J32="","",IF(J32=G32,1,0))
A33: 1 | B33: 46258.38 | C33: N | D33: 0.878 | E33: EST | F33: 120.478 | G33: N | H33: =IF(C33=G33,1,0) -> 1 | I33: 1 | J33: N | K33: =IF(J33="","",IF(J33=G33,1,0)) -> 1
A34: 1 | B34: 46258.38 | C34: H | D34: 0.886 | E34: EST | F34: 118.405 | G34: H | H34: =IF(C34=G34,1,0) -> 1 | K34: =IF(J34="","",IF(J34=G34,1,0))
A35: 1 | B35: 46258.38 | C35: D | D35: 0.982 | E35: EST | F35: 89.718 | G35: D | H35: =IF(C35=G35,1,0) -> 1 | K35: =IF(J35="","",IF(J35=G35,1,0))
A36: 1 | B36: 46258.38 | C36: I | D36: 0.909 | E36: EST | F36: 116.793 | G36: I | H36: =IF(C36=G36,1,0) -> 1 | K36: =IF(J36="","",IF(J36=G36,1,0))
A37: 1 | B37: 46258.38 | C37: N | D37: 0.802 | E37: EST | F37: 126.372 | G37: N | H37: =IF(C37=G37,1,0) -> 1 | K37: =IF(J37="","",IF(J37=G37,1,0))
A38: 1 | B38: 46258.381 | C38: Z | D38: 0.851 | E38: DIN | F38: 153.343 | G38: Z | H38: =IF(C38=G38,1,0) -> 1 | I38: 1 | J38: Z | K38: =IF(J38="","",IF(J38=G38,1,0)) -> 1
A39: 1 | B39: 46258.381 | C39: B | D39: 0.837 | E39: EST | F39: 143.535 | G39: B | H39: =IF(C39=G39,1,0) -> 1 | K39: =IF(J39="","",IF(J39=G39,1,0))
A40: 1 | B40: 46258.381 | C40: E | D40: 0.837 | E40: EST | F40: 88.716 | G40: E | H40: =IF(C40=G40,1,0) -> 1 | K40: =IF(J40="","",IF(J40=G40,1,0))
...

Sheet Tabla_General
A1: usuario_id | B1: timestamp_inicio | C1: timestamp_fin | D1: total_reconocimientos | E1: tiempo_prueba_segundos | F1: letras_unicas | G1: confianza_promedio | H1: confianza_min | I1: confianza_max | J1: confianza_std | K1: latencia_promedio_ms | L1: latencia_min_ms | M1: latencia_max_ms | N1: latencia_std_ms | O1: signos_correctos | P1: precision_% | Q1: tasa_error_%
A2: 1 | B2: 46258.375 | C2: =B2+E2/86400 -> 46258.384 | D2: =COUNTIF(Detalle!$A$2:$A$687,$A2) -> 49 | E2: 702 | F2: =SUMPRODUCT((Detalle!$A$2:$A$687=$A2)/COUNTIFS(Detalle!$A$2:$A$687,Detalle!$A$2:$A$687,Detalle!$C$2:$C$687,Detalle!$C$2:$C$687)) -> 25 | G2: =AVERAGEIFS(Detalle!$D$2:$D$687,Detalle!$A$2:$A$687,$A2) -> 0.85855102 | H2: =_xlfn.MINIFS(Detalle!$D$2:$D$687,Detalle!$A$2:$A$687,$A2) -> 0.697 | I2: =_xlfn.MAXIFS(Detalle!$D$2:$D$687,Detalle!$A$2:$A$687,$A2) -> 0.982 | J2: =SQRT(SUMPRODUCT((Detalle!$A$2:$A$687=$A2)*(Detalle!$D$2:$D$687-G2)^2)/(D2-1)) -> 0.062867606 | K2: =AVERAGEIFS(Detalle!$F$2:$F$687,Detalle!$A$2:$A$687,$A2) -> 115.23745 | L2: =_xlfn.MINIFS(Detalle!$F$2:$F$687,Detalle!$A$2:$A$687,$A2) -> 85 | M2: =_xlfn.MAXIFS(Detalle!$F$2:$F$687,Detalle!$A$2:$A$687,$A2) -> 153.343 | N2: =SQRT(SUMPRODUCT((Detalle!$A$2:$A$687=$A2)*(Detalle!$F$2:$F$687-K2)^2)/(D2-1)) -> 17.481215 | O2: =SUMIFS(Detalle!$H$2:$H$687,Detalle!$A$2:$A$687,$A2) -> 44 | P2: =O2/D2*100 -> 89.795918 | Q2: =100-P2 -> 10.204082
A3: 2 | B3: 46258.388 | C3: =B3+E3/86400 -> 46258.396 | D3: =COUNTIF(Detalle!$A$2:$A$687,$A3) -> 51 | E3: 730 | F3: =SUMPRODUCT((Detalle!$A$2:$A$687=$A3)/COUNTIFS(Detalle!$A$2:$A$687,Detalle!$A$2:$A$687,Detalle!$C$2:$C$687,Detalle!$C$2:$C$687)) -> 24 | G3: =AVERAGEIFS(Detalle!$D$2:$D$687,Detalle!$A$2:$A$687,$A3) -> 0.89627451 | H3: =_xlfn.MINIFS(Detalle!$D$2:$D$687,Detalle!$A$2:$A$687,$A3) -> 0.687 | I3: =_xlfn.MAXIFS(Detalle!$D$2:$D$687,Detalle!$A$2:$A$687,$A3) -> 0.99 | J3: =SQRT(SUMPRODUCT((Detalle!$A$2:$A$687=$A3)*(Detalle!$D$2:$D$687-G3)^2)/(D3-1)) -> 0.067022109 | K3: =AVERAGEIFS(Detalle!$F$2:$F$687,Detalle!$A$2:$A$687,$A3) -> 117.80459 | L3: =_xlfn.MINIFS(Detalle!$F$2:$F$687,Detalle!$A$2:$A$687,$A3) -> 85 | M3: =_xlfn.MAXIFS(Detalle!$F$2:$F$687,Detalle!$A$2:$A$687,$A3) -> 174.966 | N3: =SQRT(SUMPRODUCT((Detalle!$A$2:$A$687=$A3)*(Detalle!$F$2:$F$687-K3)^2)/(D3-1)) -> 22.051755 | O3: =SUMIFS(Detalle!$H$2:$H$687,Detalle!$A$2:$A$687,$A3) -> 41 | P3: =O3/D3*100 -> 80.392157 | Q3: =100-P3 -> 19.607843
A4: 3 | B4: 46258.408 | C4: =B4+E4/86400 -> 46258.415 | D4: =COUNTIF(Detalle!$A$2:$A$687,$A4) -> 56 | E4: 648 | F4: =SUMPRODUCT((Detalle!$A$2:$A$687=$A4)/COUNTIFS(Detalle!$A$2:$A$687,Detalle!$A$2:$A$687,Detalle!$C$2:$C$687,Detalle!$C$2:$C$687)) -> 21 | G4: =AVERAGEIFS(Detalle!$D$2:$D$687,Detalle!$A$2:$A$687,$A4) -> 0.88051786 | H4: =_xlfn.MINIFS(Detalle!$D$2:$D$687,Detalle!$A$2:$A$687,$A4) -> 0.698 | I4: =_xlfn.MAXIFS(Detalle!$D$2:$D$687,Detalle!$A$2:$A$687,$A4) -> 0.99 | J4: =SQRT(SUMPRODUCT((Detalle!$A$2:$A$687=$A4)*(Detalle!$D$2:$D$687-G4)^2)/(D4-1)) -> 0.069004082 | K4: =AVERAGEIFS(Detalle!$F$2:$F$687,Detalle!$A$2:$A$687,$A4) -> 117.15398 | L4: =_xlfn.MINIFS(Detalle!$F$2:$F$687,Detalle!$A$2:$A$687,$A4) -> 85 | M4: =_xlfn.MAXIFS(Detalle!$F$2:$F$687,Detalle!$A$2:$A$687,$A4) -> 162.519 | N4: =SQRT(SUMPRODUCT((Detalle!$A$2:$A$687=$A4)*(Detalle!$F$2:$F$687-K4)^2)/(D4-1)) -> 19.390647 | O4: =SUMIFS(Detalle!$H$2:$H$687,Detalle!$A$2:$A$687,$A4) -> 49 | P4: =O4/D4*100 -> 87.5 | Q4: =100-P4 -> 12.5
A5: 4 | B5: 46258.422 | C5: =B5+E5/86400 -> 46258.43 | D5: =COUNTIF(Detalle!$A$2:$A$687,$A5) -> 34 | E5: 730 | F5: =SUMPRODUCT((Detalle!$A$2:$A$687=$A5)/COUNTIFS(Detalle!$A$2:$A$687,Detalle!$A$2:$A$687,Detalle!$C$2:$C$687,Detalle!$C$2:$C$687)) -> 21 | G5: =AVERAGEIFS(Detalle!$D$2:$D$687,Detalle!$A$2:$A$687,$A5) -> 0.88032353 | H5: =_xlfn.MINIFS(Detalle!$D$2:$D$687,Detalle!$A$2:$A$687,$A5) -> 0.692 | I5: =_xlfn.MAXIFS(Detalle!$D$2:$D$687,Detalle!$A$2:$A$687,$A5) -> 0.99 | J5: =SQRT(SUMPRODUCT((Detalle!$A$2:$A$687=$A5)*(Detalle!$D$2:$D$687-G5)^2)/(D5-1)) -> 0.072478929 | K5: =AVERAGEIFS(Detalle!$F$2:$F$687,Detalle!$A$2:$A$687,$A5) -> 123.89356 | L5: =_xlfn.MINIFS(Detalle!$F$2:$F$687,Detalle!$A$2:$A$687,$A5) -> 88.977 | M5: =_xlfn.MAXIFS(Detalle!$F$2:$F$687,Detalle!$A$2:$A$687,$A5) -> 171.841 | N5: =SQRT(SUMPRODUCT((Detalle!$A$2:$A$687=$A5)*(Detalle!$F$2:$F$687-K5)^2)/(D5-1)) -> 22.263558 | O5: =SUMIFS(Detalle!$H$2:$H$687,Detalle!$A$2:$A$687,$A5) -> 30 | P5: =O5/D5*100 -> 88.235294 | Q5: =100-P5 -> 11.764706
A6: 5 | B6: 46258.438 | C6: =B6+E6/86400 -> 46258.446 | D6: =COUNTIF(Detalle!$A$2:$A$687,$A6) -> 44 | E6: 691 | F6: =SUMPRODUCT((Detalle!$A$2:$A$687=$A6)/COUNTIFS(Detalle!$A$2:$A$687,Detalle!$A$2:$A$687,Detalle!$C$2:$C$687,Detalle!$C$2:$C$687)) -> 24 | G6: =AVERAGEIFS(Detalle!$D$2:$D$687,Detalle!$A$2:$A$687,$A6) -> 0.85990909 | H6: =_xlfn.MINIFS(Detalle!$D$2:$D$687,Detalle!$A$2:$A$687,$A6) -> 0.661 | I6: =_xlfn.MAXIFS(Detalle!$D$2:$D$687,Detalle!$A$2:$A$687,$A6) -> 0.99 | J6: =SQRT(SUMPRODUCT((Detalle!$A$2:$A$687=$A6)*(Detalle!$D$2:$D$687-G6)^2)/(D6-1)) -> 0.067697624 | K6: =AVERAGEIFS(Detalle!$F$2:$F$687,Detalle!$A$2:$A$687,$A6) -> 123.16505 | L6: =_xlfn.MINIFS(Detalle!$F$2:$F$687,Detalle!$A$2:$A$687,$A6) -> 85 | M6: =_xlfn.MAXIFS(Detalle!$F$2:$F$687,Detalle!$A$2:$A$687,$A6) -> 163.681 | N6: =SQRT(SUMPRODUCT((Detalle!$A$2:$A$687=$A6)*(Detalle!$F$2:$F$687-K6)^2)/(D6-1)) -> 19.139973 | O6: =SUMIFS(Detalle!$H$2:$H$687,Detalle!$A$2:$A$687,$A6) -> 38 | P6: =O6/D6*100 -> 86.363636 | Q6: =100-P6 -> 13.636364
A7: 6 | B7: 46258.449 | C7: =B7+E7/86400 -> 46258.457 | D7: =COUNTIF(Detalle!$A$2:$A$687,$A7) -> 33 | E7: 705 | F7: =SUMPRODUCT((Detalle!$A$2:$A$687=$A7)/COUNTIFS(Detalle!$A$2:$A$687,Detalle!$A$2:$A$687,Detalle!$C$2:$C$687,Detalle!$C$2:$C$687)) -> 22 | G7: =AVERAGEIFS(Detalle!$D$2:$D$687,Detalle!$A$2:$A$687,$A7) -> 0.84860606 | H7: =_xlfn.MINIFS(Detalle!$D$2:$D$687,Detalle!$A$2:$A$687,$A7) -> 0.668 | I7: =_xlfn.MAXIFS(Detalle!$D$2:$D$687,Detalle!$A$2:$A$687,$A7) -> 0.974 | J7: =SQRT(SUMPRODUCT((Detalle!$A$2:$A$687=$A7)*(Detalle!$D$2:$D$687-G7)^2)/(D7-1)) -> 0.064179406 | K7: =AVERAGEIFS(Detalle!$F$2:$F$687,Detalle!$A$2:$A$687,$A7) -> 130.09373 | L7: =_xlfn.MINIFS(Detalle!$F$2:$F$687,Detalle!$A$2:$A$687,$A7) -> 87.856 | M7: =_xlfn.MAXIFS(Detalle!$F$2:$F$687,Detalle!$A$2:$A$687,$A7) -> 159.883 | N7: =SQRT(SUMPRODUCT((Detalle!$A$2:$A$687=$A7)*(Detalle!$F$2:$F$687-K7)^2)/(D7-1)) -> 17.252075 | O7: =SUMIFS(Detalle!$H$2:$H$687,Detalle!$A$2:$A$687,$A7) -> 29 | P7: =O7/D7*100 -> 87.878788 | Q7: =100-P7 -> 12.121212
A8: 7 | B8: 46258.459 | C8: =B8+E8/86400 -> 46258.469 | D8: =COUNTIF(Detalle!$A$2:$A$687,$A8) -> 54 | E8: 851 | F8: =SUMPRODUCT((Detalle!$A$2:$A$687=$A8)/COUNTIFS(Detalle!$A$2:$A$687,Detalle!$A$2:$A$687,Detalle!$C$2:$C$687,Detalle!$C$2:$C$687)) -> 24 | G8: =AVERAGEIFS(Detalle!$D$2:$D$687,Detalle!$A$2:$A$687,$A8) -> 0.8615 | H8: =_xlfn.MINIFS(Detalle!$D$2:$D$687,Detalle!$A$2:$A$687,$A8) -> 0.695 | I8: =_xlfn.MAXIFS(Detalle!$D$2:$D$687,Detalle!$A$2:$A$687,$A8) -> 0.984 | J8: =SQRT(SUMPRODUCT((Detalle!$A$2:$A$687=$A8)*(Detalle!$D$2:$D$687-G8)^2)/(D8-1)) -> 0.067687336 | K8: =AVERAGEIFS(Detalle!$F$2:$F$687,Detalle!$A$2:$A$687,$A8) -> 122.20778 | L8: =_xlfn.MINIFS(Detalle!$F$2:$F$687,Detalle!$A$2:$A$687,$A8) -> 85 | M8: =_xlfn.MAXIFS(Detalle!$F$2:$F$687,Detalle!$A$2:$A$687,$A8) -> 162.217 | N8: =SQRT(SUMPRODUCT((Detalle!$A$2:$A$687=$A8)*(Detalle!$F$2:$F$687-K8)^2)/(D8-1)) -> 20.562799 | O8: =SUMIFS(Detalle!$H$2:$H$687,Detalle!$A$2:$A$687,$A8) -> 43 | P8: =O8/D8*100 -> 79.62963 | Q8: =100-P8 -> 20.37037
A9: 8 | B9: 46258.472 | C9: =B9+E9/86400 -> 46258.479 | D9: =COUNTIF(Detalle!$A$2:$A$687,$A9) -> 42 | E9: 614 | F9: =SUMPRODUCT((Detalle!$A$2:$A$687=$A9)/COUNTIFS(Detalle!$A$2:$A$687,Detalle!$A$2:$A$687,Detalle!$C$2:$C$687,Detalle!$C$2:$C$687)) -> 21 | G9: =AVERAGEIFS(Detalle!$D$2:$D$687,Detalle!$A$2:$A$687,$A9) -> 0.84295238 | H9: =_xlfn.MINIFS(Detalle!$D$2:$D$687,Detalle!$A$2:$A$687,$A9) -> 0.655 | I9: =_xlfn.MAXIFS(Detalle!$D$2:$D$687,Detalle!$A$2:$A$687,$A9) -> 0.979 | J9: =SQRT(SUMPRODUCT((Detalle!$A$2:$A$687=$A9)*(Detalle!$D$2:$D$687-G9)^2)/(D9-1)) -> 0.070772722 | K9: =AVERAGEIFS(Detalle!$F$2:$F$687,Detalle!$A$2:$A$687,$A9) -> 111.30762 | L9: =_xlfn.MINIFS(Detalle!$F$2:$F$687,Detalle!$A$2:$A$687,$A9) -> 85 | M9: =_xlfn.MAXIFS(Detalle!$F$2:$F$687,Detalle!$A$2:$A$687,$A9) -> 146.123 | N9: =SQRT(SUMPRODUCT((Detalle!$A$2:$A$687=$A9)*(Detalle!$F$2:$F$687-K9)^2)/(D9-1)) -> 18.259968 | O9: =SUMIFS(Detalle!$H$2:$H$687,Detalle!$A$2:$A$687,$A9) -> 35 | P9: =O9/D9*100 -> 83.333333 | Q9: =100-P9 -> 16.666667
A10: 9 | B10: 46258.483 | C10: =B10+E10/86400 -> 46258.493 | D10: =COUNTIF(Detalle!$A$2:$A$687,$A10) -> 39 | E10: 860 | F10: =SUMPRODUCT((Detalle!$A$2:$A$687=$A10)/COUNTIFS(Detalle!$A$2:$A$687,Detalle!$A$2:$A$687,Detalle!$C$2:$C$687,Detalle!$C$2:$C$687)) -> 25 | G10: =AVERAGEIFS(Detalle!$D$2:$D$687,Detalle!$A$2:$A$687,$A10) -> 0.88612821 | H10: =_xlfn.MINIFS(Detalle!$D$2:$D$687,Detalle!$A$2:$A$687,$A10) -> 0.739 | I10: =_xlfn.MAXIFS(Detalle!$D$2:$D$687,Detalle!$A$2:$A$687,$A10) -> 0.987 | J10: =SQRT(SUMPRODUCT((Detalle!$A$2:$A$687=$A10)*(Detalle!$D$2:$D$687-G10)^2)/(D10-1)) -> 0.065111313 | K10: =AVERAGEIFS(Detalle!$F$2:$F$687,Detalle!$A$2:$A$687,$A10) -> 121.04662 | L10: =_xlfn.MINIFS(Detalle!$F$2:$F$687,Detalle!$A$2:$A$687,$A10) -> 85 | M10: =_xlfn.MAXIFS(Detalle!$F$2:$F$687,Detalle!$A$2:$A$687,$A10) -> 150.55 | N10: =SQRT(SUMPRODUCT((Detalle!$A$2:$A$687=$A10)*(Detalle!$F$2:$F$687-K10)^2)/(D10-1)) -> 16.947396 | O10: =SUMIFS(Detalle!$H$2:$H$687,Detalle!$A$2:$A$687,$A10) -> 35 | P10: =O10/D10*100 -> 89.74359 | Q10: =100-P10 -> 10.25641
A11: 10 | B11: 46258.493 | C11: =B11+E11/86400 -> 46258.502 | D11: =COUNTIF(Detalle!$A$2:$A$687,$A11) -> 37 | E11: 771 | F11: =SUMPRODUCT((Detalle!$A$2:$A$687=$A11)/COUNTIFS(Detalle!$A$2:$A$687,Detalle!$A$2:$A$687,Detalle!$C$2:$C$687,Detalle!$C$2:$C$687)) -> 23 | G11: =AVERAGEIFS(Detalle!$D$2:$D$687,Detalle!$A$2:$A$687,$A11) -> 0.90864865 | H11: =_xlfn.MINIFS(Detalle!$D$2:$D$687,Detalle!$A$2:$A$687,$A11) -> 0.799 | I11: =_xlfn.MAXIFS(Detalle!$D$2:$D$687,Detalle!$A$2:$A$687,$A11) -> 0.99 | J11: =SQRT(SUMPRODUCT((Detalle!$A$2:$A$687=$A11)*(Detalle!$D$2:$D$687-G11)^2)/(D11-1)) -> 0.060355988 | K11: =AVERAGEIFS(Detalle!$F$2:$F$687,Detalle!$A$2:$A$687,$A11) -> 126.87073 | L11: =_xlfn.MINIFS(Detalle!$F$2:$F$687,Detalle!$A$2:$A$687,$A11) -> 85.819 | M11: =_xlfn.MAXIFS(Detalle!$F$2:$F$687,Detalle!$A$2:$A$687,$A11) -> 180.551 | N11: =SQRT(SUMPRODUCT((Detalle!$A$2:$A$687=$A11)*(Detalle!$F$2:$F$687-K11)^2)/(D11-1)) -> 21.371521 | O11: =SUMIFS(Detalle!$H$2:$H$687,Detalle!$A$2:$A$687,$A11) -> 31 | P11: =O11/D11*100 -> 83.783784 | Q11: =100-P11 -> 16.216216
A12: 11 | B12: 46258.506 | C12: =B12+E12/86400 -> 46258.516 | D12: =COUNTIF(Detalle!$A$2:$A$687,$A12) -> 44 | E12: 806 | F12: =SUMPRODUCT((Detalle!$A$2:$A$687=$A12)/COUNTIFS(Detalle!$A$2:$A$687,Detalle!$A$2:$A$687,Detalle!$C$2:$C$687,Detalle!$C$2:$C$687)) -> 22 | G12: =AVERAGEIFS(Detalle!$D$2:$D$687,Detalle!$A$2:$A$687,$A12) -> 0.83784091 | H12: =_xlfn.MINIFS(Detalle!$D$2:$D$687,Detalle!$A$2:$A$687,$A12) -> 0.658 | I12: =_xlfn.MAXIFS(Detalle!$D$2:$D$687,Detalle!$A$2:$A$687,$A12) -> 0.951 | J12: =SQRT(SUMPRODUCT((Detalle!$A$2:$A$687=$A12)*(Detalle!$D$2:$D$687-G12)^2)/(D12-1)) -> 0.073504609 | K12: =AVERAGEIFS(Detalle!$F$2:$F$687,Detalle!$A$2:$A$687,$A12) -> 127.53616 | L12: =_xlfn.MINIFS(Detalle!$F$2:$F$687,Detalle!$A$2:$A$687,$A12) -> 98.526 | M12: =_xlfn.MAXIFS(Detalle!$F$2:$F$687,Detalle!$A$2:$A$687,$A12) -> 159.118 | N12: =SQRT(SUMPRODUCT((Detalle!$A$2:$A$687=$A12)*(Detalle!$F$2:$F$687-K12)^2)/(D12-1)) -> 14.063983 | O12: =SUMIFS(Detalle!$H$2:$H$687,Detalle!$A$2:$A$687,$A12) -> 38 | P12: =O12/D12*100 -> 86.363636 | Q12: =100-P12 -> 13.636364
A13: 12 | B13: 46258.522 | C13: =B13+E13/86400 -> 46258.531 | D13: =COUNTIF(Detalle!$A$2:$A$687,$A13) -> 44 | E13: 836 | F13: =SUMPRODUCT((Detalle!$A$2:$A$687=$A13)/COUNTIFS(Detalle!$A$2:$A$687,Detalle!$A$2:$A$687,Detalle!$C$2:$C$687,Detalle!$C$2:$C$687)) -> 23 | G13: =AVERAGEIFS(Detalle!$D$2:$D$687,Detalle!$A$2:$A$687,$A13) -> 0.87502273 | H13: =_xlfn.MINIFS(Detalle!$D$2:$D$687,Detalle!$A$2:$A$687,$A13) -> 0.744 | I13: =_xlfn.MAXIFS(Detalle!$D$2:$D$687,Detalle!$A$2:$A$687,$A13) -> 0.969 | J13: =SQRT(SUMPRODUCT((Detalle!$A$2:$A$687=$A13)*(Detalle!$D$2:$D$687-G13)^2)/(D13-1)) -> 0.051144796 | K13: =AVERAGEIFS(Detalle!$F$2:$F$687,Detalle!$A$2:$A$687,$A13) -> 133.74598 | L13: =_xlfn.MINIFS(Detalle!$F$2:$F$687,Detalle!$A$2:$A$687,$A13) -> 98.132 | M13: =_xlfn.MAXIFS(Detalle!$F$2:$F$687,Detalle!$A$2:$A$687,$A13) -> 184.572 | N13: =SQRT(SUMPRODUCT((Detalle!$A$2:$A$687=$A13)*(Detalle!$F$2:$F$687-K13)^2)/(D13-1)) -> 21.65231 | O13: =SUMIFS(Detalle!$H$2:$H$687,Detalle!$A$2:$A$687,$A13) -> 41 | P13: =O13/D13*100 -> 93.181818 | Q13: =100-P13 -> 6.8181818
... A16: 15 | B16: 46258.561 | C16: =B16+E16/86400 -> 46258.57 | D16: =COUNTIF(Detalle!$A$2:$A$687,$A16) -> 53 | E16: 759 | F16: =SUMPRODUCT((Detalle!$A$2:$A$687=$A16)/COUNTIFS(Detalle!$A$2:$A$687,Detalle!$A$2:$A$687,Detalle!$C$2:$C$687,Detalle!$C$2:$C$687)) -> 22 | G16: =AVERAGEIFS(Detalle!$D$2:$D$687,Detalle!$A$2:$A$687,$A16) -> 0.86901887 | H16: =_xlfn.MINIFS(Detalle!$D$2:$D$687,Detalle!$A$2:$A$687,$A16) -> 0.679 | I16: =_xlfn.MAXIFS(Detalle!$D$2:$D$687,Detalle!$A$2:$A$687,$A16) -> 0.99 | J16: =SQRT(SUMPRODUCT((Detalle!$A$2:$A$687=$A16)*(Detalle!$D$2:$D$687-G16)^2)/(D16-1)) -> 0.071023693 | K16: =AVERAGEIFS(Detalle!$F$2:$F$687,Detalle!$A$2:$A$687,$A16) -> 124.58932 | L16: =_xlfn.MINIFS(Detalle!$F$2:$F$687,Detalle!$A$2:$A$687,$A16) -> 85.757 | M16: =_xlfn.MAXIFS(Detalle!$F$2:$F$687,Detalle!$A$2:$A$687,$A16) -> 175.099 | N16: =SQRT(SUMPRODUCT((Detalle!$A$2:$A$687=$A16)*(Detalle!$F$2:$F$687-K16)^2)/(D16-1)) -> 19.503087 | O16: =SUMIFS(Detalle!$H$2:$H$687,Detalle!$A$2:$A$687,$A16) -> 46 | P16: =O16/D16*100 -> 86.792453 | Q16: =100-P16 -> 13.207547
A17: Global | D17: =SUM(D2:D16) -> 686 | O17: =SUM(O2:O16) -> 587 | P17: =O17/D17*100 -> 85.568513 | Q17: =100-P17 -> 14.431487

Sheet Tabla_Por_Letra
A1: usuario_id | B1: Letra | C1: Reconocimientos | D1: Confianza Promedio | E1: Confianza Min | F1: Confianza Max | G1: Latencia Promedio (ms) | H1: Latencia Min (ms) | I1: Latencia Max (ms)
A2: 1 | B2: A | C2: =COUNTIFS(Detalle!$A$2:$A$687,$A2,Detalle!$C$2:$C$687,$B2) -> 1 | D2: =AVERAGEIFS(Detalle!$D$2:$D$687,Detalle!$A$2:$A$687,$A2,Detalle!$C$2:$C$687,$B2) -> 0.748 | E2: =_xlfn.MINIFS(Detalle!$D$2:$D$687,Detalle!$A$2:$A$687,$A2,Detalle!$C$2:$C$687,$B2) -> 0.748 | F2: =_xlfn.MAXIFS(Detalle!$D$2:$D$687,Detalle!$A$2:$A$687,$A2,Detalle!$C$2:$C$687,$B2) -> 0.748 | G2: =AVERAGEIFS(Detalle!$F$2:$F$687,Detalle!$A$2:$A$687,$A2,Detalle!$C$2:$C$687,$B2) -> 113.026 | H2: =_xlfn.MINIFS(Detalle!$F$2:$F$687,Detalle!$A$2:$A$687,$A2,Detalle!$C$2:$C$687,$B2) -> 113.026 | I2: =_xlfn.MAXIFS(Detalle!$F$2:$F$687,Detalle!$A$2:$A$687,$A2,Detalle!$C$2:$C$687,$B2) -> 113.026
A3: 1 | B3: B | C3: =COUNTIFS(Detalle!$A$2:$A$687,$A3,Detalle!$C$2:$C$687,$B3) -> 3 | D3: =AVERAGEIFS(Detalle!$D$2:$D$687,Detalle!$A$2:$A$687,$A3,Detalle!$C$2:$C$687,$B3) -> 0.838 | E3: =_xlfn.MINIFS(Detalle!$D$2:$D$687,Detalle!$A$2:$A$687,$A3,Detalle!$C$2:$C$687,$B3) -> 0.745 | F3: =_xlfn.MAXIFS(Detalle!$D$2:$D$687,Detalle!$A$2:$A$687,$A3,Detalle!$C$2:$C$687,$B3) -> 0.932 | G3: =AVERAGEIFS(Detalle!$F$2:$F$687,Detalle!$A$2:$A$687,$A3,Detalle!$C$2:$C$687,$B3) -> 123.434 | H3: =_xlfn.MINIFS(Detalle!$F$2:$F$687,Detalle!$A$2:$A$687,$A3,Detalle!$C$2:$C$687,$B3) -> 107.976 | I3: =_xlfn.MAXIFS(Detalle!$F$2:$F$687,Detalle!$A$2:$A$687,$A3,Detalle!$C$2:$C$687,$B3) -> 143.535
A4: 1 | B4: C | C4: =COUNTIFS(Detalle!$A$2:$A$687,$A4,Detalle!$C$2:$C$687,$B4) -> 1 | D4: =AVERAGEIFS(Detalle!$D$2:$D$687,Detalle!$A$2:$A$687,$A4,Detalle!$C$2:$C$687,$B4) -> 0.868 | E4: =_xlfn.MINIFS(Detalle!$D$2:$D$687,Detalle!$A$2:$A$687,$A4,Detalle!$C$2:$C$687,$B4) -> 0.868 | F4: =_xlfn.MAXIFS(Detalle!$D$2:$D$687,Detalle!$A$2:$A$687,$A4,Detalle!$C$2:$C$687,$B4) -> 0.868 | G4: =AVERAGEIFS(Detalle!$F$2:$F$687,Detalle!$A$2:$A$687,$A4,Detalle!$C$2:$C$687,$B4) -> 118.138 | H4: =_xlfn.MINIFS(Detalle!$F$2:$F$687,Detalle!$A$2:$A$687,$A4,Detalle!$C$2:$C$687,$B4) -> 118.138 | I4: =_xlfn.MAXIFS(Detalle!$F$2:$F$687,Detalle!$A$2:$A$687,$A4,Detalle!$C$2:$C$687,$B4) -> 118.138
A5: 1 | B5: D | C5: =COUNTIFS(Detalle!$A$2:$A$687,$A5,Detalle!$C$2:$C$687,$B5) -> 2 | D5: =AVERAGEIFS(Detalle!$D$2:$D$687,Detalle!$A$2:$A$687,$A5,Detalle!$C$2:$C$687,$B5) -> 0.9565 | E5: =_xlfn.MINIFS(Detalle!$D$2:$D$687,Detalle!$A$2:$A$687,$A5,Detalle!$C$2:$C$687,$B5) -> 0.931 | F5: =_xlfn.MAXIFS(Detalle!$D$2:$D$687,Detalle!$A$2:$A$687,$A5,Detalle!$C$2:$C$687,$B5) -> 0.982 | G5: =AVERAGEIFS(Detalle!$F$2:$F$687,Detalle!$A$2:$A$687,$A5,Detalle!$C$2:$C$687,$B5) -> 87.359 | H5: =_xlfn.MINIFS(Detalle!$F$2:$F$687,Detalle!$A$2:$A$687,$A5,Detalle!$C$2:$C$687,$B5) -> 85 | I5: =_xlfn.MAXIFS(Detalle!$F$2:$F$687,Detalle!$A$2:$A$687,$A5,Detalle!$C$2:$C$687,$B5) -> 89.718
A6: 1 | B6: E | C6: =COUNTIFS(Detalle!$A$2:$A$687,$A6,Detalle!$C$2:$C$687,$B6) -> 2 | D6: =AVERAGEIFS(Detalle!$D$2:$D$687,Detalle!$A$2:$A$687,$A6,Detalle!$C$2:$C$687,$B6) -> 0.8715 | E6: =_xlfn.MINIFS(Detalle!$D$2:$D$687,Detalle!$A$2:$A$687,$A6,Detalle!$C$2:$C$687,$B6) -> 0.837 | F6: =_xlfn.MAXIFS(Detalle!$D$2:$D$687,Detalle!$A$2:$A$687,$A6,Detalle!$C$2:$C$687,$B6) -> 0.906 | G6: =AVERAGEIFS(Detalle!$F$2:$F$687,Detalle!$A$2:$A$687,$A6,Detalle!$C$2:$C$687,$B6) -> 104.638 | H6: =_xlfn.MINIFS(Detalle!$F$2:$F$687,Detalle!$A$2:$A$687,$A6,Detalle!$C$2:$C$687,$B6) -> 88.716 | I6: =_xlfn.MAXIFS(Detalle!$F$2:$F$687,Detalle!$A$2:$A$687,$A6,Detalle!$C$2:$C$687,$B6) -> 120.56
A7: 1 | B7: F | C7: =COUNTIFS(Detalle!$A$2:$A$687,$A7,Detalle!$C$2:$C$687,$B7) -> 1 | D7: =AVERAGEIFS(Detalle!$D$2:$D$687,Detalle!$A$2:$A$687,$A7,Detalle!$C$2:$C$687,$B7) -> 0.697 | E7: =_xlfn.MINIFS(Detalle!$D$2:$D$687,Detalle!$A$2:$A$687,$A7,Detalle!$C$2:$C$687,$B7) -> 0.697 | F7: =_xlfn.MAXIFS(Detalle!$D$2:$D$687,Detalle!$A$2:$A$687,$A7,Detalle!$C$2:$C$687,$B7) -> 0.697 | G7: =AVERAGEIFS(Detalle!$F$2:$F$687,Detalle!$A$2:$A$687,$A7,Detalle!$C$2:$C$687,$B7) -> 138.804 | H7: =_xlfn.MINIFS(Detalle!$F$2:$F$687,Detalle!$A$2:$A$687,$A7,Detalle!$C$2:$C$687,$B7) -> 138.804 | I7: =_xlfn.MAXIFS(Detalle!$F$2:$F$687,Detalle!$A$2:$A$687,$A7,Detalle!$C$2:$C$687,$B7) -> 138.804
A8: 1 | B8: G | C8: =COUNTIFS(Detalle!$A$2:$A$687,$A8,Detalle!$C$2:$C$687,$B8) -> 1 | D8: =AVERAGEIFS(Detalle!$D$2:$D$687,Detalle!$A$2:$A$687,$A8,Detalle!$C$2:$C$687,$B8) -> 0.886 | E8: =_xlfn.MINIFS(Detalle!$D$2:$D$687,Detalle!$A$2:$A$687,$A8,Detalle!$C$2:$C$687,$B8) -> 0.886 | F8: =_xlfn.MAXIFS(Detalle!$D$2:$D$687,Detalle!$A$2:$A$687,$A8,Detalle!$C$2:$C$687,$B8) -> 0.886 | G8: =AVERAGEIFS(Detalle!$F$2:$F$687,Detalle!$A$2:$A$687,$A8,Detalle!$C$2:$C$687,$B8) -> 119.482 | H8: =_xlfn.MINIFS(Detalle!$F$2:$F$687,Detalle!$A$2:$A$687,$A8,Detalle!$C$2:$C$687,$B8) -> 119.482 | I8: =_xlfn.MAXIFS(Detalle!$F$2:$F$687,Detalle!$A$2:$A$687,$A8,Detalle!$C$2:$C$687,$B8) -> 119.482
A9: 1 | B9: H | C9: =COUNTIFS(Detalle!$A$2:$A$687,$A9,Detalle!$C$2:$C$687,$B9) -> 3 | D9: =AVERAGEIFS(Detalle!$D$2:$D$687,Detalle!$A$2:$A$687,$A9,Detalle!$C$2:$C$687,$B9) -> 0.88466667 | E9: =_xlfn.MINIFS(Detalle!$D$2:$D$687,Detalle!$A$2:$A$687,$A9,Detalle!$C$2:$C$687,$B9) -> 0.859 | F9: =_xlfn.MAXIFS(Detalle!$D$2:$D$687,Detalle!$A$2:$A$687,$A9,Detalle!$C$2:$C$687,$B9) -> 0.909 | G9: =AVERAGEIFS(Detalle!$F$2:$F$687,Detalle!$A$2:$A$687,$A9,Detalle!$C$2:$C$687,$B9) -> 117.067 | H9: =_xlfn.MINIFS(Detalle!$F$2:$F$687,Detalle!$A$2:$A$687,$A9,Detalle!$C$2:$C$687,$B9) -> 110.227 | I9: =_xlfn.MAXIFS(Detalle!$F$2:$F$687,Detalle!$A$2:$A$687,$A9,Detalle!$C$2:$C$687,$B9) -> 122.569
A10: 1 | B10: I | C10: =COUNTIFS(Detalle!$A$2:$A$687,$A10,Detalle!$C$2:$C$687,$B10) -> 4 | D10: =AVERAGEIFS(Detalle!$D$2:$D$687,Detalle!$A$2:$A$687,$A10,Detalle!$C$2:$C$687,$B10) -> 0.82225 | E10: =_xlfn.MINIFS(Detalle!$D$2:$D$687,Detalle!$A$2:$A$687,$A10,Detalle!$C$2:$C$687,$B10) -> 0.733 | F10: =_xlfn.MAXIFS(Detalle!$D$2:$D$687,Detalle!$A$2:$A$687,$A10,Detalle!$C$2:$C$687,$B10) -> 0.909 | G10: =AVERAGEIFS(Detalle!$F$2:$F$687,Detalle!$A$2:$A$687,$A10,Detalle!$C$2:$C$687,$B10) -> 110.45475 | H10: =_xlfn.MINIFS(Detalle!$F$2:$F$687,Detalle!$A$2:$A$687,$A10,Detalle!$C$2:$C$687,$B10) -> 97.323 | I10: =_xlfn.MAXIFS(Detalle!$F$2:$F$687,Detalle!$A$2:$A$687,$A10,Detalle!$C$2:$C$687,$B10) -> 129.003
A11: 1 | B11: J | C11: =COUNTIFS(Detalle!$A$2:$A$687,$A11,Detalle!$C$2:$C$687,$B11) -> 3 | D11: =AVERAGEIFS(Detalle!$D$2:$D$687,Detalle!$A$2:$A$687,$A11,Detalle!$C$2:$C$687,$B11) -> 0.84533333 | E11: =_xlfn.MINIFS(Detalle!$D$2:$D$687,Detalle!$A$2:$A$687,$A11,Detalle!$C$2:$C$687,$B11) -> 0.766 | F11: =_xlfn.MAXIFS(Detalle!$D$2:$D$687,Detalle!$A$2:$A$687,$A11,Detalle!$C$2:$C$687,$B11) -> 0.912 | G11: =AVERAGEIFS(Detalle!$F$2:$F$687,Detalle!$A$2:$A$687,$A11,Detalle!$C$2:$C$687,$B11) -> 131.57767 | H11: =_xlfn.MINIFS(Detalle!$F$2:$F$687,Detalle!$A$2:$A$687,$A11,Detalle!$C$2:$C$687,$B11) -> 127.228 | I11: =_xlfn.MAXIFS(Detalle!$F$2:$F$687,Detalle!$A$2:$A$687,$A11,Detalle!$C$2:$C$687,$B11) -> 134.811
A12: 1 | B12: K | C12: =COUNTIFS(Detalle!$A$2:$A$687,$A12,Detalle!$C$2:$C$687,$B12) -> 1 | D12: =AVERAGEIFS(Detalle!$D$2:$D$687,Detalle!$A$2:$A$687,$A12,Detalle!$C$2:$C$687,$B12) -> 0.908 | E12: =_xlfn.MINIFS(Detalle!$D$2:$D$687,Detalle!$A$2:$A$687,$A12,Detalle!$C$2:$C$687,$B12) -> 0.908 | F12: =_xlfn.MAXIFS(Detalle!$D$2:$D$687,Detalle!$A$2:$A$687,$A12,Detalle!$C$2:$C$687,$B12) -> 0.908 | G12: =AVERAGEIFS(Detalle!$F$2:$F$687,Detalle!$A$2:$A$687,$A12,Detalle!$C$2:$C$687,$B12) -> 116.417 | H12: =_xlfn.MINIFS(Detalle!$F$2:$F$687,Detalle!$A$2:$A$687,$A12,Detalle!$C$2:$C$687,$B12) -> 116.417 | I12: =_xlfn.MAXIFS(Detalle!$F$2:$F$687,Detalle!$A$2:$A$687,$A12,Detalle!$C$2:$C$687,$B12) -> 116.417
A13: 1 | B13: L | C13: =COUNTIFS(Detalle!$A$2:$A$687,$A13,Detalle!$C$2:$C$687,$B13) -> 2 | D13: =AVERAGEIFS(Detalle!$D$2:$D$687,Detalle!$A$2:$A$687,$A13,Detalle!$C$2:$C$687,$B13) -> 0.8195 | E13: =_xlfn.MINIFS(Detalle!$D$2:$D$687,Detalle!$A$2:$A$687,$A13,Detalle!$C$2:$C$687,$B13) -> 0.809 | F13: =_xlfn.MAXIFS(Detalle!$D$2:$D$687,Detalle!$A$2:$A$687,$A13,Detalle!$C$2:$C$687,$B13) -> 0.83 | G13: =AVERAGEIFS(Detalle!$F$2:$F$687,Detalle!$A$2:$A$687,$A13,Detalle!$C$2:$C$687,$B13) -> 125.9635 | H13: =_xlfn.MINIFS(Detalle!$F$2:$F$687,Detalle!$A$2:$A$687,$A13,Detalle!$C$2:$C$687,$B13) -> 117.91 | I13: =_xlfn.MAXIFS(Detalle!$F$2:$F$687,Detalle!$A$2:$A$687,$A13,Detalle!$C$2:$C$687,$B13) -> 134.017
... A345: 15 | B345: Z | C345: =COUNTIFS(Detalle!$A$2:$A$687,$A345,Detalle!$C$2:$C$687,$B345) -> 2 | D345: =AVERAGEIFS(Detalle!$D$2:$D$687,Detalle!$A$2:$A$687,$A345,Detalle!$C$2:$C$687,$B345) -> 0.94 | E345: =_xlfn.MINIFS(Detalle!$D$2:$D$687,Detalle!$A$2:$A$687,$A345,Detalle!$C$2:$C$687,$B345) -> 0.931 | F345: =_xlfn.MAXIFS(Detalle!$D$2:$D$687,Detalle!$A$2:$A$687,$A345,Detalle!$C$2:$C$687,$B345) -> 0.949 | G345: =AVERAGEIFS(Detalle!$F$2:$F$687,Detalle!$A$2:$A$687,$A345,Detalle!$C$2:$C$687,$B345) -> 159.44 | H345: =_xlfn.MINIFS(Detalle!$F$2:$F$687,Detalle!$A$2:$A$687,$A345,Detalle!$C$2:$C$687,$B345) -> 143.781 | I345: =_xlfn.MAXIFS(Detalle!$F$2:$F$687,Detalle!$A$2:$A$687,$A345,Detalle!$C$2:$C$687,$B345) -> 175.099
A347: Total de reconocimientos (debe igualar Detalle): | F347: =SUM(C2:C345) -> 686
A348: Aviso: la letra de esta tabla es la predicha por el guante (como en tu formato original).

Sheet Metricas_Tesis
A1: Métricas de la variable dependiente
A3: Métrica | B3: Valor | C3: Unidad | D3: Cómo se calcula
A4: Precisión de transmisión (PST) | B4: =SUM(Detalle!$H$2:$H$687)/COUNTA(Detalle!$A$2:$A$687)*100 -> 85.568513 | C4: % | D4: PST = signos bien traducidos / total de signos ejecutados × 100
A5: Comprensión del mensaje (PCM) | B5: =B11/B10*100 -> 81.777778 | C5: % | D5: PCM = mensajes comprendidos correctamente / total de mensajes evaluados × 100
A6: Latencia promedio de comunicación (LPC) | B6: =AVERAGE(Detalle!$F$2:$F$687) -> 122.36781 | C6: ms | D6: LPC = t_respuesta − t_ejecución, promediado sobre todos los signos
A7: Tasa de error (TE) | B7: =COUNTIF(Detalle!$H$2:$H$687,0)/COUNTA(Detalle!$A$2:$A$687)*100 -> 14.431487 | C7: % | D7: TE = signos incorrectamente traducidos / total de signos ejecutados × 100
A9: Datos del receptor oyente (calculados desde Detalle, columnas I-K)
A10: Total de mensajes evaluados (letras evaluadas por el oyente) | B10: =COUNT(Detalle!$K$2:$K$687) -> 225
A11: Mensajes comprendidos correctamente | B11: =SUM(Detalle!$K$2:$K$687) -> 184
A12: Control: PST + TE (debe ser 100) | B12: =B4+B7 -> 100
A14: Desglose por tipo de modelo (según letra predicha)
A15: Modelo | B15: Signos | C15: Precisión (%) | D15: Latencia promedio (ms)
A16: EST (estáticas) | B16: =COUNTIF(Detalle!$E$2:$E$687,"EST") -> 618 | C16: =SUMIFS(Detalle!$H$2:$H$687,Detalle!$E$2:$E$687,"EST")/B16*100 -> 85.760518 | D16: =AVERAGEIFS(Detalle!$F$2:$F$687,Detalle!$E$2:$E$687,"EST") -> 120.04036
A17: DIN (dinámicas: J, Z, Ñ) | B17: =COUNTIF(Detalle!$E$2:$E$687,"DIN") -> 68 | C17: =SUMIFS(Detalle!$H$2:$H$687,Detalle!$E$2:$E$687,"DIN")/B17*100 -> 83.823529 | D17: =AVERAGEIFS(Detalle!$F$2:$F$687,Detalle!$E$2:$E$687,"DIN") -> 143.52028
A19: Percepción de uso: proviene del cuestionario, no incluido en esta plantilla.
